Workbook
Name taylor_swift_spotify_1: 'Raw Data'!$B$2:$B$584

Sheet Raw Data
B2: ,name,album,release_date,track_number,id,uri,acousticness,danceability,energy,instrumentalness,liveness,loudness,speechiness,tempo,valence,popularity,duration_ms
B3: 0,Fortnight (feat. Post Malone),THE TORTURED POETS DEPARTMENT: THE ANTHOLOGY,2024-04-19,1,6dODwocEuGzHAavXqTbwHv,spotify:track:6dODwocEuGzHAavXqTbwHv,0.502,0.504,0.386,1.53e-05,0.0961,-10.976,0.0308,192.004,0.281,82,228965
B4: 1,The Tortured Poets Department,THE TORTURED POETS DEPARTMENT: THE ANTHOLOGY,2024-04-19,2,4PdLaGZubp4lghChqp8erB,spotify:track:4PdLaGZubp4lghChqp8erB,0.0483,0.604,0.428,0.0,0.126,-8.441,0.0255,110.259,0.292,79,293048
B5: 2,My Boy Only Breaks His Favorite Toys,THE TORTURED POETS DEPARTMENT: THE ANTHOLOGY,2024-04-19,3,7uGYWMwRy24dm7RUDDhUlD,spotify:track:7uGYWMwRy24dm7RUDDhUlD,0.137,0.596,0.563,0.0,0.302,-7.362,0.0269,97.073,0.481,80,203801
B6: 3,Down Bad,THE TORTURED POETS DEPARTMENT: THE ANTHOLOGY,2024-04-19,4,1kbEbBdEgQdQeLXCJh28pJ,spotify:track:1kbEbBdEgQdQeLXCJh28pJ,0.56,0.541,0.366,1e-06,0.0946,-10.412,0.0748,159.707,0.168,82,261228
B7: 4,"So Long, London",THE TORTURED POETS DEPARTMENT: THE ANTHOLOGY,2024-04-19,5,7wAkQFShJ27V8362MqevQr,spotify:track:7wAkQFShJ27V8362MqevQr,0.73,0.423,0.533,0.00264,0.0816,-11.388,0.322,160.218,0.248,80,262974
B8: 5,But Daddy I Love Him,THE TORTURED POETS DEPARTMENT: THE ANTHOLOGY,2024-04-19,6,4QMgEffJQuKtjCNvqfRZ0m,spotify:track:4QMgEffJQuKtjCNvqfRZ0m,0.384,0.521,0.72,0.0,0.135,-7.684,0.104,79.943,0.438,81,340428
B9: 6,Fresh Out The Slammer,THE TORTURED POETS DEPARTMENT: THE ANTHOLOGY,2024-04-19,7,7IWcDWOfiooH5hRs9XOVYz,spotify:track:7IWcDWOfiooH5hRs9XOVYz,0.624,0.33,0.483,0.0,0.111,-9.394,0.0399,87.115,0.34,78,210789
B10: 7,Florida!!! (feat. Florence + The Machine),THE TORTURED POETS DEPARTMENT: THE ANTHOLOGY,2024-04-19,8,5ExOm0dh4NyRyAdSAO9hyM,spotify:track:5ExOm0dh4NyRyAdSAO9hyM,0.178,0.533,0.573,0.0,0.309,-7.123,0.138,150.088,0.398,79,215463
B11: 8,Guilty as Sin?,THE TORTURED POETS DEPARTMENT: THE ANTHOLOGY,2024-04-19,9,799KrpEbhZp0MHeiA8YK9P,spotify:track:799KrpEbhZp0MHeiA8YK9P,0.607,0.626,0.428,0.0,0.0921,-8.374,0.0261,94.95,0.487,82,254365
B12: 9,Who’s Afraid of Little Old Me?,THE TORTURED POETS DEPARTMENT: THE ANTHOLOGY,2024-04-19,10,2d8UxVNhJinc8uat9PoM9y,spotify:track:2d8UxVNhJinc8uat9PoM9y,0.315,0.606,0.338,0.0,0.106,-10.555,0.048,119.88,0.238,81,334084
B13: 10,I Can Fix Him (No Really I Can),THE TORTURED POETS DEPARTMENT: THE ANTHOLOGY,2024-04-19,11,5chnRTB9qMK3W1M41SnU9s,spotify:track:5chnRTB9qMK3W1M41SnU9s,0.768,0.661,0.257,1.72e-06,0.176,-13.961,0.045,106.896,0.318,77,156297
... B584: 581,Teardrops on My Guitar - Pop Version,Taylor Swift (Deluxe Edition),2006-10-24,15,1hxLyjC9D9Jpw6EAPKqWv4,spotify:track:1hxLyjC9D9Jpw6EAPKqWv4,0.0402,0.459,0.753,0.0,0.0863,-3.827,0.0537,199.997,0.483,55,179066

Sheet Clean Data
B2: name | C2: album | D2: release_date | E2: track_number | F2: acousticness | G2: danceability | H2: energy | I2: instrumentalness | J2: liveness | K2: loudness | L2: speechiness | M2: tempo | N2: valence | O2: popularity | P2: duration_ms | Q2: year | R2: duration_ms2 | S2: mood_category | T2: energy_category | U2: popularity_group
B3: Fortnight (feat. Post Malone) | C3: THE TORTURED POETS DEPARTMENT: THE ANTHOLOGY | D3: 45401 | E3: 1 | F3: 0.34861111 | G3: 0.35 | H3: 0.26805556 | I3: 1.53e-05 | J3: 0.66736111 | K3: -10976 | L3: 0.21388889 | M3: 192004 | N3: 0.19513889 | O3: 82 | P3: 228965 | Q3: =YEAR(Table13[[#This Row],[release_date]]) -> 2024 | R3: =ROUND(Table13[[#This Row],[duration_ms]]/60000,2) -> 3.82 | S3: =IF(Table13[[#This Row],[valence]]>=0.6, "Happy", IF(Table13[[#This Row],[valence]]>=0.4, "Neutral", "Sad")) -> Sad | T3: =IF(Table13[[#This Row],[energy]]>=0.7, "High Energy", IF(Table13[[#This Row],[energy]]>=0.4, "Medium Energy", "Low Energy")) -> Low Energy | U3: =IF(Table13[[#This Row],[popularity]]>70, "Popular", IF(Table13[[#This Row],[popularity]]<40, "Less Popular", "Mid")) -> Popular
B4: The Tortured Poets Department | C4: THE TORTURED POETS DEPARTMENT: THE ANTHOLOGY | D4: 45401 | E4: 2 | F4: 0.33541667 | G4: 0.41944444 | H4: 0.29722222 | I4: 0 | J4: 0.0875 | K4: -8441 | L4: 0.17708333 | M4: 110259 | N4: 0.20277778 | O4: 79 | P4: 293048 | Q4: =YEAR(Table13[[#This Row],[release_date]]) -> 2024 | R4: =ROUND(Table13[[#This Row],[duration_ms]]/60000,2) -> 4.88 | S4: =IF(Table13[[#This Row],[valence]]>=0.6, "Happy", IF(Table13[[#This Row],[valence]]>=0.4, "Neutral", "Sad")) -> Sad | T4: =IF(Table13[[#This Row],[energy]]>=0.7, "High Energy", IF(Table13[[#This Row],[energy]]>=0.4, "Medium Energy", "Low Energy")) -> Low Energy | U4: =IF(Table13[[#This Row],[popularity]]>70, "Popular", IF(Table13[[#This Row],[popularity]]<40, "Less Popular", "Mid")) -> Popular
B5: My Boy Only Breaks His Favorite Toys | C5: THE TORTURED POETS DEPARTMENT: THE ANTHOLOGY | D5: 45401 | E5: 3 | F5: 0.095138889 | G5: 0.41388889 | H5: 0.39097222 | I5: 0 | J5: 0.20972222 | K5: -7362 | L5: 0.18680556 | M5: 97073 | N5: 0.33402778 | O5: 80 | P5: 203801 | Q5: =YEAR(Table13[[#This Row],[release_date]]) -> 2024 | R5: =ROUND(Table13[[#This Row],[duration_ms]]/60000,2) -> 3.4 | S5: =IF(Table13[[#This Row],[valence]]>=0.6, "Happy", IF(Table13[[#This Row],[valence]]>=0.4, "Neutral", "Sad")) -> Sad | T5: =IF(Table13[[#This Row],[energy]]>=0.7, "High Energy", IF(Table13[[#This Row],[energy]]>=0.4, "Medium Energy", "Low Energy")) -> Low Energy | U5: =IF(Table13[[#This Row],[popularity]]>70, "Popular", IF(Table13[[#This Row],[popularity]]<40, "Less Popular", "Mid")) -> Popular
B6: Down Bad | C6: THE TORTURED POETS DEPARTMENT: THE ANTHOLOGY | D6: 45401 | E6: 4 | F6: 0.038888889 | G6: 0.37569444 | H6: 0.25416667 | I6: 1e-06 | J6: 0.65694444 | K6: -10412 | L6: 0.51944444 | M6: 159707 | N6: 0.11666667 | O6: 82 | P6: 261228 | Q6: =YEAR(Table13[[#This Row],[release_date]]) -> 2024 | R6: =ROUND(Table13[[#This Row],[duration_ms]]/60000,2) -> 4.35 | S6: =IF(Table13[[#This Row],[valence]]>=0.6, "Happy", IF(Table13[[#This Row],[valence]]>=0.4, "Neutral", "Sad")) -> Sad | T6: =IF(Table13[[#This Row],[energy]]>=0.7, "High Energy", IF(Table13[[#This Row],[energy]]>=0.4, "Medium Energy", "Low Energy")) -> Low Energy | U6: =IF(Table13[[#This Row],[popularity]]>70, "Popular", IF(Table13[[#This Row],[popularity]]<40, "Less Popular", "Mid")) -> Popular
B7: So Long, London | C7: THE TORTURED POETS DEPARTMENT: THE ANTHOLOGY | D7: 45401 | E7: 5 | F7: 0.050694444 | G7: 0.29375 | H7: 0.37013889 | I7: 0.00264 | J7: 0.56666667 | K7: -11388 | L7: 0.22361111 | M7: 160218 | N7: 0.17222222 | O7: 80 | P7: 262974 | Q7: =YEAR(Table13[[#This Row],[release_date]]) -> 2024 | R7: =ROUND(Table13[[#This Row],[duration_ms]]/60000,2) -> 4.38 | S7: =IF(Table13[[#This Row],[valence]]>=0.6, "Happy", IF(Table13[[#This Row],[valence]]>=0.4, "Neutral", "Sad")) -> Sad | T7: =IF(Table13[[#This Row],[energy]]>=0.7, "High Energy", IF(Table13[[#This Row],[energy]]>=0.4, "Medium Energy", "Low Energy")) -> Low Energy | U7: =IF(Table13[[#This Row],[popularity]]>70, "Popular", IF(Table13[[#This Row],[popularity]]<40, "Less Popular", "Mid")) -> Popular
B8: But Daddy I Love Him | C8: THE TORTURED POETS DEPARTMENT: THE ANTHOLOGY | D8: 45401 | E8: 6 | F8: 0.26666667 | G8: 0.36180556 | H8: 0.05 | I8: 0 | J8: 0.09375 | K8: -7684 | L8: 0.072222222 | M8: 79943 | N8: 0.30416667 | O8: 81 | P8: 340428 | Q8: =YEAR(Table13[[#This Row],[release_date]]) -> 2024 | R8: =ROUND(Table13[[#This Row],[duration_ms]]/60000,2) -> 5.67 | S8: =IF(Table13[[#This Row],[valence]]>=0.6, "Happy", IF(Table13[[#This Row],[valence]]>=0.4, "Neutral", "Sad")) -> Sad | T8: =IF(Table13[[#This Row],[energy]]>=0.7, "High Energy", IF(Table13[[#This Row],[energy]]>=0.4, "Medium Energy", "Low Energy")) -> Low Energy | U8: =IF(Table13[[#This Row],[popularity]]>70, "Popular", IF(Table13[[#This Row],[popularity]]<40, "Less Popular", "Mid")) -> Popular
B9: Fresh Out The Slammer | C9: THE TORTURED POETS DEPARTMENT: THE ANTHOLOGY | D9: 45401 | E9: 7 | F9: 0.43333333 | G9: 0.022916667 | H9: 0.33541667 | I9: 0 | J9: 0.077083333 | K9: -9394 | L9: 0.27708333 | M9: 87115 | N9: 0.023611111 | O9: 78 | P9: 210789 | Q9: =YEAR(Table13[[#This Row],[release_date]]) -> 2024 | R9: =ROUND(Table13[[#This Row],[duration_ms]]/60000,2) -> 3.51 | S9: =IF(Table13[[#This Row],[valence]]>=0.6, "Happy", IF(Table13[[#This Row],[valence]]>=0.4, "Neutral", "Sad")) -> Sad | T9: =IF(Table13[[#This Row],[energy]]>=0.7, "High Energy", IF(Table13[[#This Row],[energy]]>=0.4, "Medium Energy", "Low Energy")) -> Low Energy | U9: =IF(Table13[[#This Row],[popularity]]>70, "Popular", IF(Table13[[#This Row],[popularity]]<40, "Less Popular", "Mid")) -> Popular
B10: Florida!!! (feat. Florence + The Machine) | C10: THE TORTURED POETS DEPARTMENT: THE ANTHOLOGY | D10: 45401 | E10: 8 | F10: 0.12361111 | G10: 0.37013889 | H10: 0.39791667 | I10: 0 | J10: 0.21458333 | K10: -7123 | L10: 0.095833333 | M10: 150088 | N10: 0.27638889 | O10: 79 | P10: 215463 | Q10: =YEAR(Table13[[#This Row],[release_date]]) -> 2024 | R10: =ROUND(Table13[[#This Row],[duration_ms]]/60000,2) -> 3.59 | S10: =IF(Table13[[#This Row],[valence]]>=0.6, "Happy", IF(Table13[[#This Row],[valence]]>=0.4, "Neutral", "Sad")) -> Sad | T10: =IF(Table13[[#This Row],[energy]]>=0.7, "High Energy", IF(Table13[[#This Row],[energy]]>=0.4, "Medium Energy", "Low Energy")) -> Low Energy | U10: =IF(Table13[[#This Row],[popularity]]>70, "Popular", IF(Table13[[#This Row],[popularity]]<40, "Less Popular", "Mid")) -> Popular
B11: Guilty as Sin? | C11: THE TORTURED POETS DEPARTMENT: THE ANTHOLOGY | D11: 45401 | E11: 9 | F11: 0.42152778 | G11: 0.43472222 | H11: 0.29722222 | I11: 0 | J11: 0.63958333 | K11: -8374 | L11: 0.18125 | M11: 94.95 | N11: 0.33819444 | O11: 82 | P11: 254365 | Q11: =YEAR(Table13[[#This Row],[release_date]]) -> 2024 | R11: =ROUND(Table13[[#This Row],[duration_ms]]/60000,2) -> 4.24 | S11: =IF(Table13[[#This Row],[valence]]>=0.6, "Happy", IF(Table13[[#This Row],[valence]]>=0.4, "Neutral", "Sad")) -> Sad | T11: =IF(Table13[[#This Row],[energy]]>=0.7, "High Energy", IF(Table13[[#This Row],[energy]]>=0.4, "Medium Energy", "Low Energy")) -> Low Energy | U11: =IF(Table13[[#This Row],[popularity]]>70, "Popular", IF(Table13[[#This Row],[popularity]]<40, "Less Popular", "Mid")) -> Popular
B12: Who’s Afraid of Little Old Me? | C12: THE TORTURED POETS DEPARTMENT: THE ANTHOLOGY | D12: 45401 | E12: 10 | F12: 0.21875 | G12: 0.42083333 | H12: 0.23472222 | I12: 0 | J12: 0.073611111 | K12: -10555 | L12: 0.048 | M12: 119.88 | N12: 0.16527778 | O12: 81 | P12: 334084 | Q12: =YEAR(Table13[[#This Row],[release_date]]) -> 2024 | R12: =ROUND(Table13[[#This Row],[duration_ms]]/60000,2) -> 5.57 | S12: =IF(Table13[[#This Row],[valence]]>=0.6, "Happy", IF(Table13[[#This Row],[valence]]>=0.4, "Neutral", "Sad")) -> Sad | T12: =IF(Table13[[#This Row],[energy]]>=0.7, "High Energy", IF(Table13[[#This Row],[energy]]>=0.4, "Medium Energy", "Low Energy")) -> Low Energy | U12: =IF(Table13[[#This Row],[popularity]]>70, "Popular", IF(Table13[[#This Row],[popularity]]<40, "Less Popular", "Mid")) -> Popular
B13: I Can Fix Him (No Really I Can) | C13: THE TORTURED POETS DEPARTMENT: THE ANTHOLOGY | D13: 45401 | E13: 11 | F13: 0.53333333 | G13: 0.45902778 | H13: 0.17847222 | I13: 1.72e-06 | J13: 0.12222222 | K13: -13961 | L13: 0.045 | M13: 106896 | N13: 0.22083333 | O13: 77 | P13: 156297 | Q13: =YEAR(Table13[[#This Row],[release_date]]) -> 2024 | R13: =ROUND(Table13[[#This Row],[duration_ms]]/60000,2) -> 2.6 | S13: =IF(Table13[[#This Row],[valence]]>=0.6, "Happy", IF(Table13[[#This Row],[valence]]>=0.4, "Neutral", "Sad")) -> Sad | T13: =IF(Table13[[#This Row],[energy]]>=0.7, "High Energy", IF(Table13[[#This Row],[energy]]>=0.4, "Medium Energy", "Low Energy")) -> Low Energy | U13: =IF(Table13[[#This Row],[popularity]]>70, "Popular", IF(Table13[[#This Row],[popularity]]<40, "Less Popular", "Mid")) -> Popular
B14: loml | C14: THE TORTURED POETS DEPARTMENT: THE ANTHOLOGY | D14: 45401 | E14: 12 | F14: 0.59583333 | G14: 0.29375 | H14: 0.18888889 | I14: 0 | J14: 0.075 | K14: -12.56 | L14: 0.33958333 | M14: 78539 | N14: 0.13541667 | O14: 80 | P14: 277156 | Q14: =YEAR(Table13[[#This Row],[release_date]]) -> 2024 | R14: =ROUND(Table13[[#This Row],[duration_ms]]/60000,2) -> 4.62 | S14: =IF(Table13[[#This Row],[valence]]>=0.6, "Happy", IF(Table13[[#This Row],[valence]]>=0.4, "Neutral", "Sad")) -> Sad | T14: =IF(Table13[[#This Row],[energy]]>=0.7, "High Energy", IF(Table13[[#This Row],[energy]]>=0.4, "Medium Energy", "Low Energy")) -> Low Energy | U14: =IF(Table13[[#This Row],[popularity]]>70, "Popular", IF(Table13[[#This Row],[popularity]]<40, "Less Popular", "Mid")) -> Popular
B15: I Can Do It With a Broken Heart | C15: THE TORTURED POETS DEPARTMENT: THE ANTHOLOGY | D15: 45401 | E15: 13 | F15: 0.085416667 | G15: 0.48680556 | H15: 0.52152778 | I15: 0 | J15: 0.010416667 | K15: -8.39 | L15: 0.34861111 | M15: 129994 | N15: 0.015277778 | O15: 82 | P15: 218004 | Q15: =YEAR(Table13[[#This Row],[release_date]]) -> 2024 | R15: =ROUND(Table13[[#This Row],[duration_ms]]/60000,2) -> 3.63 | S15: =IF(Table13[[#This Row],[valence]]>=0.6, "Happy", IF(Table13[[#This Row],[valence]]>=0.4, "Neutral", "Sad")) -> Sad | T15: =IF(Table13[[#This Row],[energy]]>=0.7, "High Energy", IF(Table13[[#This Row],[energy]]>=0.4, "Medium Energy", "Low Energy")) -> Medium Energy | U15: =IF(Table13[[#This Row],[popularity]]>70, "Popular", IF(Table13[[#This Row],[popularity]]<40, "Less Popular", "Mid")) -> Popular
B16: The Smallest Man Who Ever Lived | C16: THE TORTURED POETS DEPARTMENT: THE ANTHOLOGY | D16: 45401 | E16: 14 | F16: 0.036111111 | G16: 0.29583333 | H16: 0.028472222 | I16: 0 | J16: 0.23472222 | K16: -9083 | L16: 0.40347222 | M16: 142377 | N16: 0.18263889 | O16: 81 | P16: 245541 | Q16: =YEAR(Table13[[#This Row],[release_date]]) -> 2024 | R16: =ROUND(Table13[[#This Row],[duration_ms]]/60000,2) -> 4.09 | S16: =IF(Table13[[#This Row],[valence]]>=0.6, "Happy", IF(Table13[[#This Row],[valence]]>=0.4, "Neutral", "Sad")) -> Sad | T16: =IF(Table13[[#This Row],[energy]]>=0.7, "High Energy", IF(Table13[[#This Row],[energy]]>=0.4, "Medium Energy", "Low Energy")) -> Low Energy | U16: =IF(Table13[[#This Row],[popularity]]>70, "Popular", IF(Table13[[#This Row],[popularity]]<40, "Less Popular", "Mid")) -> Popular
B17: The Alchemy | C17: THE TORTURED POETS DEPARTMENT: THE ANTHOLOGY | D17: 45401 | E17: 15 | F17: 0.29305556 | G17: 0.044444444 | H17: 0.29236111 | I17: 0 | J17: 0.071527778 | K17: -8802 | L17: 0.18958333 | M17: 100056 | N17: 0.24513889 | O17: 78 | P17: 196900 | Q17: =YEAR(Table13[[#This Row],[release_date]]) -> 2024 | R17: =ROUND(Table13[[#This Row],[duration_ms]]/60000,2) -> 3.28 | S17: =IF(Table13[[#This Row],[valence]]>=0.6, "Happy", IF(Table13[[#This Row],[valence]]>=0.4, "Neutral", "Sad")) -> Sad | T17: =IF(Table13[[#This Row],[energy]]>=0.7, "High Energy", IF(Table13[[#This Row],[energy]]>=0.4, "Medium Energy", "Low Energy")) -> Low Energy | U17: =IF(Table13[[#This Row],[popularity]]>70, "Popular", IF(Table13[[#This Row],[popularity]]<40, "Less Popular", "Mid")) -> Popular
B18: Clara Bow | C18: THE TORTURED POETS DEPARTMENT: THE ANTHOLOGY | D18: 45401 | E18: 16 | F18: 0.44166667 | G18: 0.47638889 | H18: 0.22083333 | I18: 0.00144 | J18: 0.073611111 | K18: -11046 | L18: 0.18263889 | M18: 104088 | N18: 0.14861111 | O18: 76 | P18: 216662 | Q18: =YEAR(Table13[[#This Row],[release_date]]) -> 2024 | R18: =ROUND(Table13[[#This Row],[duration_ms]]/60000,2) -> 3.61 | S18: =IF(Table13[[#This Row],[valence]]>=0.6, "Happy", IF(Table13[[#This Row],[valence]]>=0.4, "Neutral", "Sad")) -> Sad | T18: =IF(Table13[[#This Row],[energy]]>=0.7, "High Energy", IF(Table13[[#This Row],[energy]]>=0.4, "Medium Energy", "Low Energy")) -> Low Energy | U18: =IF(Table13[[#This Row],[popularity]]>70, "Popular", IF(Table13[[#This Row],[popularity]]<40, "Less Popular", "Mid")) -> Popular
B19: The Black Dog | C19: THE TORTURED POETS DEPARTMENT: THE ANTHOLOGY | D19: 45401 | E19: 17 | F19: 0.49097222 | G19: 0.36597222 | H19: 0.01875 | I19: 0 | J19: 0.070833333 | K19: -10855 | L19: 0.038 | M19: 154042 | N19: 0.015972222 | O19: 79 | P19: 238857 | Q19: =YEAR(Table13[[#This Row],[release_date]]) -> 2024 | R19: =ROUND(Table13[[#This Row],[duration_ms]]/60000,2) -> 3.98 | S19: =IF(Table13[[#This Row],[valence]]>=0.6, "Happy", IF(Table13[[#This Row],[valence]]>=0.4, "Neutral", "Sad")) -> Sad | T19: =IF(Table13[[#This Row],[energy]]>=0.7, "High Energy", IF(Table13[[#This Row],[energy]]>=0.4, "Medium Energy", "Low Energy")) -> Low Energy | U19: =IF(Table13[[#This Row],[popularity]]>70, "Popular", IF(Table13[[#This Row],[popularity]]<40, "Less Popular", "Mid")) -> Popular
B20: imgonnagetyouback | C20: THE TORTURED POETS DEPARTMENT: THE ANTHOLOGY | D20: 45401 | E20: 18 | F20: 0.42222222 | G20: 0.54444444 | H20: 0.27152778 | I20: 0 | J20: 0.175 | K20: -9471 | L20: 0.43958333 | M20: 110007 | N20: 0.010416667 | O20: 81 | P20: 222072 | Q20: =YEAR(Table13[[#This Row],[release_date]]) -> 2024 | R20: =ROUND(Table13[[#This Row],[duration_ms]]/60000,2) -> 3.7 | S20: =IF(Table13[[#This Row],[valence]]>=0.6, "Happy", IF(Table13[[#This Row],[valence]]>=0.4, "Neutral", "Sad")) -> Sad | T20: =IF(Table13[[#This Row],[energy]]>=0.7, "High Energy", IF(Table13[[#This Row],[energy]]>=0.4, "Medium Energy", "Low Energy")) -> Low Energy | U20: =IF(Table13[[#This Row],[popularity]]>70, "Popular", IF(Table13[[#This Row],[popularity]]<40, "Less Popular", "Mid")) -> Popular
B21: The Albatross | C21: THE TORTURED POETS DEPARTMENT: THE ANTHOLOGY | D21: 45401 | E21: 19 | F21: 0.45486111 | G21: 0.24444444 | H21: 0.33263889 | I21: 0 | J21: 0.64930556 | K21: -8942 | L21: 0.40486111 | M21: 172013 | N21: 0.20277778 | O21: 77 | P21: 183878 | Q21: =YEAR(Table13[[#This Row],[release_date]]) -> 2024 | R21: =ROUND(Table13[[#This Row],[duration_ms]]/60000,2) -> 3.06 | S21: =IF(Table13[[#This Row],[valence]]>=0.6, "Happy", IF(Table13[[#This Row],[valence]]>=0.4, "Neutral", "Sad")) -> Sad | T21: =IF(Table13[[#This Row],[energy]]>=0.7, "High Energy", IF(Table13[[#This Row],[energy]]>=0.4, "Medium Energy", "Low Energy")) -> Low Energy | U21: =IF(Table13[[#This Row],[popularity]]>70, "Popular", IF(Table13[[#This Row],[popularity]]<40, "Less Popular", "Mid")) -> Popular
B22: Chloe or Sam or Sophia or Marcus | C22: THE TORTURED POETS DEPARTMENT: THE ANTHOLOGY | D22: 45401 | E22: 20 | F22: 0.054166667 | G22: 0.35833333 | H22: 0.31319444 | I22: 0 | J22: 0.072916667 | K22: -8552 | L22: 0.30972222 | M22: 70266 | N22: 0.15138889 | O22: 77 | P22: 213281 | Q22: =YEAR(Table13[[#This Row],[release_date]]) -> 2024 | R22: =ROUND(Table13[[#This Row],[duration_ms]]/60000,2) -> 3.55 | S22: =IF(Table13[[#This Row],[valence]]>=0.6, "Happy", IF(Table13[[#This Row],[valence]]>=0.4, "Neutral", "Sad")) -> Sad | T22: =IF(Table13[[#This Row],[energy]]>=0.7, "High Energy", IF(Table13[[#This Row],[energy]]>=0.4, "Medium Energy", "Low Energy")) -> Low Energy | U22: =IF(Table13[[#This Row],[popularity]]>70, "Popular", IF(Table13[[#This Row],[popularity]]<40, "Less Popular", "Mid")) -> Popular
B23: How Did It End? | C23: THE TORTURED POETS DEPARTMENT: THE ANTHOLOGY | D23: 45401 | E23: 21 | F23: 0.54513889 | G23: 0.34166667 | H23: 0.26319444 | I23: 0.00093 | J23: 0.075 | K23: -8859 | L23: 0.17847222 | M23: 83993 | N23: 0.18958333 | O23: 80 | P23: 238706 | Q23: =YEAR(Table13[[#This Row],[release_date]]) -> 2024 | R23: =ROUND(Table13[[#This Row],[duration_ms]]/60000,2) -> 3.98 | S23: =IF(Table13[[#This Row],[valence]]>=0.6, "Happy", IF(Table13[[#This Row],[valence]]>=0.4, "Neutral", "Sad")) -> Sad | T23: =IF(Table13[[#This Row],[energy]]>=0.7, "High Energy", IF(Table13[[#This Row],[energy]]>=0.4, "Medium Energy", "Low Energy")) -> Low Energy | U23: =IF(Table13[[#This Row],[popularity]]>70, "Popular", IF(Table13[[#This Row],[popularity]]<40, "Less Popular", "Mid")) -> Popular
B24: So High School | C24: THE TORTURED POETS DEPARTMENT: THE ANTHOLOGY | D24: 45401 | E24: 22 | F24: 0.19027778 | G24: 0.25416667 | H24: 0.60138889 | I24: 3.07e-06 | J24: 0.073611111 | K24: -4514 | L24: 0.32361111 | M24: 7.3381944 | N24: 0.20347222 | O24: 82 | P24: 228800 | Q24: =YEAR(Table13[[#This Row],[release_date]]) -> 2024 | R24: =ROUND(Table13[[#This Row],[duration_ms]]/60000,2) -> 3.81 | S24: =IF(Table13[[#This Row],[valence]]>=0.6, "Happy", IF(Table13[[#This Row],[valence]]>=0.4, "Neutral", "Sad")) -> Sad | T24: =IF(Table13[[#This Row],[energy]]>=0.7, "High Energy", IF(Table13[[#This Row],[energy]]>=0.4, "Medium Energy", "Low Energy")) -> Medium Energy | U24: =IF(Table13[[#This Row],[popularity]]>70, "Popular", IF(Table13[[#This Row],[popularity]]<40, "Less Popular", "Mid")) -> Popular
B25: I Hate It Here | C25: THE TORTURED POETS DEPARTMENT: THE ANTHOLOGY | D25: 45401 | E25: 23 | F25: 0.49791667 | G25: 0.33680556 | H25: 0.39027778 | I25: 0 | J25: 0.24791667 | K25: -7197 | L25: 0.24027778 | M25: 105953 | N25: 0.20625 | O25: 78 | P25: 243875 | Q25: =YEAR(Table13[[#This Row],[release_date]]) -> 2024 | R25: =ROUND(Table13[[#This Row],[duration_ms]]/60000,2) -> 4.06 | S25: =IF(Table13[[#This Row],[valence]]>=0.6, "Happy", IF(Table13[[#This Row],[valence]]>=0.4, "Neutral", "Sad")) -> Sad | T25: =IF(Table13[[#This Row],[energy]]>=0.7, "High Energy", IF(Table13[[#This Row],[energy]]>=0.4, "Medium Energy", "Low Energy")) -> Low Energy | U25: =IF(Table13[[#This Row],[popularity]]>70, "Popular", IF(Table13[[#This Row],[popularity]]<40, "Less Popular", "Mid")) -> Popular
B26: thanK you aIMee | C26: THE TORTURED POETS DEPARTMENT: THE ANTHOLOGY | D26: 45401 | E26: 24 | F26: 0.42291667 | G26: 0.42291667 | H26: 0.37569444 | I26: 0 | J26: 0.084722222 | K26: -8013 | L26: 0.24027778 | M26: 95997 | N26: 0.175 | O26: 76 | P26: 263817 | Q26: =YEAR(Table13[[#This Row],[release_date]]) -> 2024 | R26: =ROUND(Table13[[#This Row],[duration_ms]]/60000,2) -> 4.4 | S26: =IF(Table13[[#This Row],[valence]]>=0.6, "Happy", IF(Table13[[#This Row],[valence]]>=0.4, "Neutral", "Sad")) -> Sad | T26: =IF(Table13[[#This Row],[energy]]>=0.7, "High Energy", IF(Table13[[#This Row],[energy]]>=0.4, "Medium Energy", "Low Energy")) -> Low Energy | U26: =IF(Table13[[#This Row],[popularity]]>70, "Popular", IF(Table13[[#This Row],[popularity]]<40, "Less Popular", "Mid")) -> Popular
B27: I Look in People's Windows | C27: THE TORTURED POETS DEPARTMENT: THE ANTHOLOGY | D27: 45401 | E27: 25 | F27: 0.047916667 | G27: 0.52986111 | H27: 0.19027778 | I27: 0 | J27: 0.11388889 | K27: -11429 | L27: 0.5125 | M27: 90796 | N27: 0.26736111 | O27: 76 | P27: 131907 | Q27: =YEAR(Table13[[#This Row],[release_date]]) -> 2024 | R27: =ROUND(Table13[[#This Row],[duration_ms]]/60000,2) -> 2.2 | S27: =IF(Table13[[#This Row],[valence]]>=0.6, "Happy", IF(Table13[[#This Row],[valence]]>=0.4, "Neutral", "Sad")) -> Sad | T27: =IF(Table13[[#This Row],[energy]]>=0.7, "High Energy", IF(Table13[[#This Row],[energy]]>=0.4, "Medium Energy", "Low Energy")) -> Low Energy | U27: =IF(Table13[[#This Row],[popularity]]>70, "Popular", IF(Table13[[#This Row],[popularity]]<40, "Less Popular", "Mid")) -> Popular
B28: The Prophecy | C28: THE TORTURED POETS DEPARTMENT: THE ANTHOLOGY | D28: 45401 | E28: 26 | F28: 0.57291667 | G28: 0.29236111 | H28: 0.36458333 | I28: 2.67e-06 | J28: 0.21388889 | K28: -10359 | L28: 0.32777778 | M28: 167927 | N28: 0.37152778 | O28: 81 | P28: 249807 | Q28: =YEAR(Table13[[#This Row],[release_date]]) -> 2024 | R28: =ROUND(Table13[[#This Row],[duration_ms]]/60000,2) -> 4.16 | S28: =IF(Table13[[#This Row],[valence]]>=0.6, "Happy", IF(Table13[[#This Row],[valence]]>=0.4, "Neutral", "Sad")) -> Sad | T28: =IF(Table13[[#This Row],[energy]]>=0.7, "High Energy", IF(Table13[[#This Row],[energy]]>=0.4, "Medium Energy", "Low Energy")) -> Low Energy | U28: =IF(Table13[[#This Row],[popularity]]>70, "Popular", IF(Table13[[#This Row],[popularity]]<40, "Less Popular", "Mid")) -> Popular
B29: Cassandra | C29: THE TORTURED POETS DEPARTMENT: THE ANTHOLOGY | D29: 45401 | E29: 27 | F29: 0.55972222 | G29: 0.40763889 | H29: 0.40763889 | I29: 0 | J29: 0.095138889 | K29: -9879 | L29: 0.41319444 | M29: 139963 | N29: 0.35694444 | O29: 76 | P29: 240205 | Q29: =YEAR(Table13[[#This Row],[release_date]]) -> 2024 | R29: =ROUND(Table13[[#This Row],[duration_ms]]/60000,2) -> 4 | S29: =IF(Table13[[#This Row],[valence]]>=0.6, "Happy", IF(Table13[[#This Row],[valence]]>=0.4, "Neutral", "Sad")) -> Sad | T29: =IF(Table13[[#This Row],[energy]]>=0.7, "High Energy", IF(Table13[[#This Row],[energy]]>=0.4, "Medium Energy", "Low Energy")) -> Medium Energy | U29: =IF(Table13[[#This Row],[popularity]]>70, "Popular", IF(Table13[[#This Row],[popularity]]<40, "Less Popular", "Mid")) -> Popular
B30: Peter | C30: THE TORTURED POETS DEPARTMENT: THE ANTHOLOGY | D30: 45401 | E30: 28 | F30: 0.55902778 | G30: 0.2375 | H30: 0.26111111 | I30: 0 | J30: 0.41180556 | K30: -8212 | L30: 0.25833333 | M30: 176859 | N30: 0.020138889 | O30: 77 | P30: 283957 | Q30: =YEAR(Table13[[#This Row],[release_date]]) -> 2024 | R30: =ROUND(Table13[[#This Row],[duration_ms]]/60000,2) -> 4.73 | S30: =IF(Table13[[#This Row],[valence]]>=0.6, "Happy", IF(Table13[[#This Row],[valence]]>=0.4, "Neutral", "Sad")) -> Sad | T30: =IF(Table13[[#This Row],[energy]]>=0.7, "High Energy", IF(Table13[[#This Row],[energy]]>=0.4, "Medium Energy", "Low Energy")) -> Low Energy | U30: =IF(Table13[[#This Row],[popularity]]>70, "Popular", IF(Table13[[#This Row],[popularity]]<40, "Less Popular", "Mid")) -> Popular
B31: The Bolter | C31: THE TORTURED POETS DEPARTMENT: THE ANTHOLOGY | D31: 45401 | E31: 29 | F31: 0.44305556 | G31: 0.31597222 | H31: 0.40694444 | I31: 0 | J31: 0.090972222 | K31: -7978 | L31: 0.34166667 | M31: 183694 | N31: 0.33402778 | O31: 77 | P31: 238241 | Q31: =YEAR(Table13[[#This Row],[release_date]]) -> 2024 | R31: =ROUND(Table13[[#This Row],[duration_ms]]/60000,2) -> 3.97 | S31: =IF(Table13[[#This Row],[valence]]>=0.6, "Happy", IF(Table13[[#This Row],[valence]]>=0.4, "Neutral", "Sad")) -> Sad | T31: =IF(Table13[[#This Row],[energy]]>=0.7, "High Energy", IF(Table13[[#This Row],[energy]]>=0.4, "Medium Energy", "Low Energy")) -> Medium Energy | U31: =IF(Table13[[#This Row],[popularity]]>70, "Popular", IF(Table13[[#This Row],[popularity]]<40, "Less Popular", "Mid")) -> Popular
B32: Robin | C32: THE TORTURED POETS DEPARTMENT: THE ANTHOLOGY | D32: 45401 | E32: 30 | F32: 0.54930556 | G32: 0.33055556 | H32: 0.26805556 | I32: 0.000423 | J32: 0.00069444444 | K32: -10601 | L32: 0.0020833333 | M32: 138265 | N32: 0.10972222 | O32: 73 | P32: 240893 | Q32: =YEAR(Table13[[#This Row],[release_date]]) -> 2024 | R32: =ROUND(Table13[[#This Row],[duration_ms]]/60000,2) -> 4.01 | S32: =IF(Table13[[#This Row],[valence]]>=0.6, "Happy", IF(Table13[[#This Row],[valence]]>=0.4, "Neutral", "Sad")) -> Sad | T32: =IF(Table13[[#This Row],[energy]]>=0.7, "High Energy", IF(Table13[[#This Row],[energy]]>=0.4, "Medium Energy", "Low Energy")) -> Low Energy | U32: =IF(Table13[[#This Row],[popularity]]>70, "Popular", IF(Table13[[#This Row],[popularity]]<40, "Less Popular", "Mid")) -> Popular
B33: The Manuscript | C33: THE TORTURED POETS DEPARTMENT: THE ANTHOLOGY | D33: 45401 | E33: 31 | F33: 0.62569444 | G33: 0.35347222 | H33: 0.17777778 | I33: 2.43e-06 | J33: 0.071527778 | K33: -11665 | L33: 0.2125 | M33: 94184 | N33: 0.30277778 | O33: 74 | P33: 224743 | Q33: =YEAR(Table13[[#This Row],[release_date]]) -> 2024 | R33: =ROUND(Table13[[#This Row],[duration_ms]]/60000,2) -> 3.75 | S33: =IF(Table13[[#This Row],[valence]]>=0.6, "Happy", IF(Table13[[#This Row],[valence]]>=0.4, "Neutral", "Sad")) -> Sad | T33: =IF(Table13[[#This Row],[energy]]>=0.7, "High Energy", IF(Table13[[#This Row],[energy]]>=0.4, "Medium Energy", "Low Energy")) -> Low Energy | U33: =IF(Table13[[#This Row],[popularity]]>70, "Popular", IF(Table13[[#This Row],[popularity]]<40, "Less Popular", "Mid")) -> Popular
B34: Fortnight (feat. Post Malone) | C34: THE TORTURED POETS DEPARTMENT | D34: 45400 | E34: 1 | F34: 0.34861111 | G34: 0.35 | H34: 0.26805556 | I34: 1.53e-05 | J34: 0.66736111 | K34: -10976 | L34: 0.21388889 | M34: 192004 | N34: 0.19513889 | O34: 91 | P34: 228965 | Q34: =YEAR(Table13[[#This Row],[release_date]]) -> 2024 | R34: =ROUND(Table13[[#This Row],[duration_ms]]/60000,2) -> 3.82 | S34: =IF(Table13[[#This Row],[valence]]>=0.6, "Happy", IF(Table13[[#This Row],[valence]]>=0.4, "Neutral", "Sad")) -> Sad | T34: =IF(Table13[[#This Row],[energy]]>=0.7, "High Energy", IF(Table13[[#This Row],[energy]]>=0.4, "Medium Energy", "Low Energy")) -> Low Energy | U34: =IF(Table13[[#This Row],[popularity]]>70, "Popular", IF(Table13[[#This Row],[popularity]]<40, "Less Popular", "Mid")) -> Popular
B35: The Tortured Poets Department | C35: THE TORTURED POETS DEPARTMENT | D35: 45400 | E35: 2 | F35: 0.33541667 | G35: 0.41944444 | H35: 0.29722222 | I35: 0 | J35: 0.0875 | K35: -8441 | L35: 0.17708333 | M35: 110259 | N35: 0.20277778 | O35: 75 | P35: 293048 | Q35: =YEAR(Table13[[#This Row],[release_date]]) -> 2024 | R35: =ROUND(Table13[[#This Row],[duration_ms]]/60000,2) -> 4.88 | S35: =IF(Table13[[#This Row],[valence]]>=0.6, "Happy", IF(Table13[[#This Row],[valence]]>=0.4, "Neutral", "Sad")) -> Sad | T35: =IF(Table13[[#This Row],[energy]]>=0.7, "High Energy", IF(Table13[[#This Row],[energy]]>=0.4, "Medium Energy", "Low Energy")) -> Low Energy | U35: =IF(Table13[[#This Row],[popularity]]>70, "Popular", IF(Table13[[#This Row],[popularity]]<40, "Less Popular", "Mid")) -> Popular
B36: My Boy Only Breaks His Favorite Toys | C36: THE TORTURED POETS DEPARTMENT | D36: 45400 | E36: 3 | F36: 0.095138889 | G36: 0.41388889 | H36: 0.39097222 | I36: 0 | J36: 0.20972222 | K36: -7362 | L36: 0.18680556 | M36: 97073 | N36: 0.33402778 | O36: 77 | P36: 203801 | Q36: =YEAR(Table13[[#This Row],[release_date]]) -> 2024 | R36: =ROUND(Table13[[#This Row],[duration_ms]]/60000,2) -> 3.4 | S36: =IF(Table13[[#This Row],[valence]]>=0.6, "Happy", IF(Table13[[#This Row],[valence]]>=0.4, "Neutral", "Sad")) -> Sad | T36: =IF(Table13[[#This Row],[energy]]>=0.7, "High Energy", IF(Table13[[#This Row],[energy]]>=0.4, "Medium Energy", "Low Energy")) -> Low Energy | U36: =IF(Table13[[#This Row],[popularity]]>70, "Popular", IF(Table13[[#This Row],[popularity]]<40, "Less Popular", "Mid")) -> Popular
B37: Down Bad | C37: THE TORTURED POETS DEPARTMENT | D37: 45400 | E37: 4 | F37: 0.038888889 | G37: 0.37569444 | H37: 0.25416667 | I37: 1e-06 | J37: 0.65694444 | K37: -10412 | L37: 0.51944444 | M37: 159707 | N37: 0.11666667 | O37: 82 | P37: 261228 | Q37: =YEAR(Table13[[#This Row],[release_date]]) -> 2024 | R37: =ROUND(Table13[[#This Row],[duration_ms]]/60000,2) -> 4.35 | S37: =IF(Table13[[#This Row],[valence]]>=0.6, "Happy", IF(Table13[[#This Row],[valence]]>=0.4, "Neutral", "Sad")) -> Sad | T37: =IF(Table13[[#This Row],[energy]]>=0.7, "High Energy", IF(Table13[[#This Row],[energy]]>=0.4, "Medium Energy", "Low Energy")) -> Low Energy | U37: =IF(Table13[[#This Row],[popularity]]>70, "Popular", IF(Table13[[#This Row],[popularity]]<40, "Less Popular", "Mid")) -> Popular
B38: So Long, London | C38: THE TORTURED POETS DEPARTMENT | D38: 45400 | E38: 5 | F38: 0.050694444 | G38: 0.29375 | H38: 0.37013889 | I38: 0.00264 | J38: 0.56666667 | K38: -11388 | L38: 0.22361111 | M38: 160218 | N38: 0.17222222 | O38: 78 | P38: 262974 | Q38: =YEAR(Table13[[#This Row],[release_date]]) -> 2024 | R38: =ROUND(Table13[[#This Row],[duration_ms]]/60000,2) -> 4.38 | S38: =IF(Table13[[#This Row],[valence]]>=0.6, "Happy", IF(Table13[[#This Row],[valence]]>=0.4, "Neutral", "Sad")) -> Sad | T38: =IF(Table13[[#This Row],[energy]]>=0.7, "High Energy", IF(Table13[[#This Row],[energy]]>=0.4, "Medium Energy", "Low Energy")) -> Low Energy | U38: =IF(Table13[[#This Row],[popularity]]>70, "Popular", IF(Table13[[#This Row],[popularity]]<40, "Less Popular", "Mid")) -> Popular
B39: But Daddy I Love Him | C39: THE TORTURED POETS DEPARTMENT | D39: 45400 | E39: 6 | F39: 0.26666667 | G39: 0.36180556 | H39: 0.05 | I39: 0 | J39: 0.09375 | K39: -7684 | L39: 0.072222222 | M39: 79943 | N39: 0.30416667 | O39: 78 | P39: 340428 | Q39: =YEAR(Table13[[#This Row],[release_date]]) -> 2024 | R39: =ROUND(Table13[[#This Row],[duration_ms]]/60000,2) -> 5.67 | S39: =IF(Table13[[#This Row],[valence]]>=0.6, "Happy", IF(Table13[[#This Row],[valence]]>=0.4, "Neutral", "Sad")) -> Sad | T39: =IF(Table13[[#This Row],[energy]]>=0.7, "High Energy", IF(Table13[[#This Row],[energy]]>=0.4, "Medium Energy", "Low Energy")) -> Low Energy | U39: =IF(Table13[[#This Row],[popularity]]>70, "Popular", IF(Table13[[#This Row],[popularity]]<40, "Less Popular", "Mid")) -> Popular
B40: Fresh Out The Slammer | C40: THE TORTURED POETS DEPARTMENT | D40: 45400 | E40: 7 | F40: 0.43333333 | G40: 0.022916667 | H40: 0.33541667 | I40: 0 | J40: 0.077083333 | K40: -9394 | L40: 0.27708333 | M40: 87115 | N40: 0.023611111 | O40: 69 | P40: 210789 | Q40: =YEAR(Table13[[#This Row],[release_date]]) -> 2024 | R40: =ROUND(Table13[[#This Row],[duration_ms]]/60000,2) -> 3.51 | S40: =IF(Table13[[#This Row],[valence]]>=0.6, "Happy", IF(Table13[[#This Row],[valence]]>=0.4, "Neutral", "Sad")) -> Sad | T40: =IF(Table13[[#This Row],[energy]]>=0.7, "High Energy", IF(Table13[[#This Row],[energy]]>=0.4, "Medium Energy", "Low Energy")) -> Low Energy | U40: =IF(Table13[[#This Row],[popularity]]>70, "Popular", IF(Table13[[#This Row],[popularity]]<40, "Less Popular", "Mid")) -> Mid
B41: Florida!!! (feat. Florence + The Machine) | C41: THE TORTURED POETS DEPARTMENT | D41: 45400 | E41: 8 | F41: 0.12361111 | G41: 0.37013889 | H41: 0.39791667 | I41: 0 | J41: 0.21458333 | K41: -7123 | L41: 0.095833333 | M41: 150088 | N41: 0.27638889 | O41: 76 | P41: 215463 | Q41: =YEAR(Table13[[#This Row],[release_date]]) -> 2024 | R41: =ROUND(Table13[[#This Row],[duration_ms]]/60000,2) -> 3.59 | S41: =IF(Table13[[#This Row],[valence]]>=0.6, "Happy", IF(Table13[[#This Row],[valence]]>=0.4, "Neutral", "Sad")) -> Sad | T41: =IF(Table13[[#This Row],[energy]]>=0.7, "High Energy", IF(Table13[[#This Row],[energy]]>=0.4, "Medium Energy", "Low Energy")) -> Low Energy | U41: =IF(Table13[[#This Row],[popularity]]>70, "Popular", IF(Table13[[#This Row],[popularity]]<40, "Less Popular", "Mid")) -> Popular
...

Sheet Pivot Table
B3: Row Labels | C3: Average of popularity | G3: Row Labels | H3: Average of duration_ms2 | J3: Row Labels | K3: Max of popularity
B4: THE TORTURED POETS DEPARTMENT: THE ANTHOLOGY | C4: 78.774194 | G4: Speak Now World Tour Live | H4: 4.95125 | J4: august | K4: 84
B5: THE TORTURED POETS DEPARTMENT | C5: 77 | G5: Speak Now | H5: 4.7871429 | J5: ...Ready For It? | K5: 82
B6: Lover | C6: 75.944444 | G6: Speak Now (Taylor's Version) | H6: 4.7604545 | J6: Anti-Hero | K6: 85
B7: reputation | C7: 75.733333 | G7: Speak Now (Deluxe Package) | H7: 4.5990909 | J7: cardigan | K7: 84
B8: Midnights | C8: 74.153846 | G8: Red (Taylor's Version) | H8: 4.3553333 | J8: Cruel Summer | K8: 93
B9: folklore | C9: 72.8125 | G9: Fearless (Platinum Edition) | H9: 4.1810526 | J9: Don’t Blame Me | K9: 85
B10: 1989 (Taylor's Version) | C10: 72.190476 | G10: Red (Deluxe Edition) | H10: 4.1213636 | J10: Down Bad | K10: 82
B11: Speak Now (Taylor's Version) | C11: 69.454545 | G11: Fearless (Taylor's Version) | H11: 4.0984615 | J11: Fortnight (feat. Post Malone) | K11: 91
B12: Red (Taylor's Version) | C12: 67.233333 | G12: THE TORTURED POETS DEPARTMENT | H12: 4.0775 | J12: Guilty as Sin? | K12: 82
B13: evermore | C13: 66.4 | G13: evermore (deluxe version) | H13: 4.0629412 | J13: I Can Do It With a Broken Heart | K13: 88
B14: Grand Total | C14: 72.908629 | G14: Red | H14: 4.056875 | J14: Lover | K14: 86
G15: evermore | H15: 4.05 | J15: So High School | K15: 82
B16: Row Labels | C16: Average of energy | G16: reputation Stadium Tour Surprise Song Playlist | H16: 4.0493478 | J16: Grand Total | K16: 93
B17: 2006 | C17: 0.4612963 | G17: Fearless (International Version) | H17: 4.00875
B18: 2008 | C18: 0.41710271 | G18: folklore | H18: 3.974375
B19: 2010 | C19: 0.44659455 | G19: folklore: the long pond studio sessions (from the Disney+ special) [deluxe edition] | H19: 3.9605882
B20: 2012 | C20: 0.39128289 | G20: THE TORTURED POETS DEPARTMENT: THE ANTHOLOGY | H20: 3.9548387
B21: 2014 | C21: 0.42078993 | G21: folklore (deluxe version) | H21: 3.9482353
B22: 2017 | C22: 0.41212432 | G22: 1989 | H22: 3.7530769
B23: 2019 | C23: 0.31404321 | G23: reputation | H23: 3.716
B24: 2020 | C24: 0.24852642 | G24: 1989 (Taylor's Version) | H24: 3.712381
B25: 2021 | C25: 0.38021309 | G25: 1989 (Taylor's Version) [Deluxe] | H25: 3.695
B26: 2022 | C26: 0.24772727 | G26: 1989 (Deluxe) | H26: 3.6189474
B27: 2023 | C27: 0.39544665 | G27: Taylor Swift (Deluxe Edition) | H27: 3.5653333
B28: 2024 | C28: 0.28289007 | G28: Midnights (The Til Dawn Edition) | H28: 3.5034783
B29: Grand Total | C29: 0.36358939 | G29: Live From Clear Channel Stripped 2008 | H29: 3.49125
G30: Midnights (3am Edition) | H30: 3.474
B31: Row Labels | C31: Average of energy | D31: Average of danceability | E31: Average of valence | G31: Lover | H31: 3.4366667
B32: 2006 | C32: 0.4612963 | D32: 0.35449074 | E32: 0.2962037 | G32: Midnights | H32: 3.3946154
B33: 2008 | C33: 0.41710271 | D33: 0.37716408 | E33: 0.24859496 | G33: Grand Total | H33: 3.9997079
B34: 2010 | C34: 0.44659455 | D34: 0.33736645 | E34: 0.2477297
B35: 2012 | C35: 0.39128289 | D35: 0.41935307 | E35: 0.32006579
B36: 2014 | C36: 0.42078993 | D36: 0.403125 | E36: 0.3202908
B37: 2017 | C37: 0.41212432 | D37: 0.37081056 | E37: 0.29314663
B38: 2019 | C38: 0.31404321 | D38: 0.43591821 | E38: 0.33433642
B39: 2020 | C39: 0.24852642 | D39: 0.34929709 | E39: 0.2199187
B40: 2021 | C40: 0.38021309 | D40: 0.36423135 | E40: 0.26696157
B41: 2022 | C41: 0.24772727 | D41: 0.35006313 | E41: 0.22609428
B42: 2023 | C42: 0.39544665 | D42: 0.36339173 | E42: 0.27151989
...

Sheet Dashboard
K73: Fitur | L73: Korelasi | N73: Nilai | O73: Arti
K74: Danceability | L74: =CORREL('Clean Data'!G3:G323, 'Clean Data'!O3:O323) -> 0.011661954 | N74: 0,7 - 1 | O74: Kuat
K75: Energy | L75: =CORREL('Clean Data'!H3:H323, 'Clean Data'!O3:O323) -> 0.17683541 | N75: 0,3 - 0,6 | O75: Sedang
K76: Velence | L76: =CORREL('Clean Data'!N3:N323, 'Clean Data'!O3:O323) -> -0.0069756293 | N76: 0 - 0,2 | O76: Lemah
K77: Tempo | L77: =CORREL('Clean Data'!M3:M323, 'Clean Data'!O3:O323) -> 0.047580086 | N77: Negatif | O77: Berlawanan
K78: Acousticness | L78: =CORREL('Clean Data'!F3:F323, 'Clean Data'!O3:O323) -> -0.21872321
